#VRML_SIM R2023b utf8

EXTERNPROTO "https://raw.githubusercontent.com/cyberbotics/webots/R2023b/projects/objects/backgrounds/protos/TexturedBackground.proto"
EXTERNPROTO "https://raw.githubusercontent.com/cyberbotics/webots/R2023b/projects/objects/backgrounds/protos/TexturedBackgroundLight.proto"
EXTERNPROTO "https://raw.githubusercontent.com/cyberbotics/webots/R2023b/projects/objects/floors/protos/RectangleArena.proto"

WorldInfo {
  info [
    "Example use of a rotating Lidar in point-cloud mode."
  ]
  title "Lidar Point-Cloud"
  basicTimeStep 8
  lineScale 0.15
}
Viewpoint {
  orientation 0.287274654615007 0.787963183343129 -0.5445982872830127 1.1798378064731017
  position -7.152934274663774 6.3562450748852966 14.74862881702897
  follow "MyBot"
}
TexturedBackground {
}
TexturedBackgroundLight {
}
RectangleArena {
  floorSize 10 10
  wallThickness 0.5
  wallHeight 1.4
}
DEF GREEN_OBJECT1 Solid {
  translation 3.0466 1.1512 0.2
  rotation 0 0 1 3.13621
  children [
    DEF BOX_SHAPE Shape {
      appearance PBRAppearance {
        baseColor 0 1 0
        roughness 0.2189099510000001
        metalness 0
      }
      geometry Box {
        size 0.4 0.8 0.4
      }
    }
  ]
  name "green object 1"
  boundingObject USE BOX_SHAPE
}
DEF GREEN_OBJECT2 Solid {
  translation 3.0576 0.5008 0.56
  rotation 0 0 1 3.13621
  children [
    USE BOX_SHAPE
  ]
  name "green object 2"
  boundingObject USE BOX_SHAPE
}
DEF GREEN_OBJECT3 Solid {
  translation 3.0481 -0.2017 0.2
  rotation 0 0 1 3.13621
  children [
    USE BOX_SHAPE
  ]
  name "green object 3"
  boundingObject USE BOX_SHAPE
}
DEF GREEN_OBJECT4 Solid {
  translation 3.0766 -2.9043 0.3
  rotation 0 0 1 3.13621
  children [
    Transform {
      scale 1.6009 1.6009 1.6009
      children [
        USE BOX_SHAPE
      ]
    }
  ]
  name "green object 4"
  boundingObject USE BOX_SHAPE
}
DEF GREEN_OBJECT5 Solid {
  translation -2.7202 -1.5167 0.3
  rotation 0 0 1 -2.623375
  children [
    Transform {
      scale 1.80916 1.80916 1.80916
      children [
        USE BOX_SHAPE
      ]
    }
  ]
  name "green object 5"
  boundingObject USE BOX_SHAPE
}
DEF BLUE_OBJECT1 Solid {
  translation 1.7069 3.5213 0.37
  rotation -0.6958897140492328 0.5078077913347121 0.5078077913347121 -1.925669
  children [
    Transform {
      scale 1.63795 1.63795 1.63795
      children [
        DEF SPHERE_SHAPE Shape {
          appearance PBRAppearance {
            baseColor 0 0 1
            roughness 0.519341125
            metalness 0
          }
          geometry Sphere {
            radius 0.35
            subdivision 2
          }
        }
      ]
    }
  ]
  name "blue object 1"
  boundingObject USE SPHERE_SHAPE
}
DEF BLUE_OBJECT2 Solid {
  translation 1.1936 -1.2416 0.27
  rotation -0.6958897140492328 0.5078077913347121 0.5078077913347121 -1.925669
  children [
    Transform {
      scale 1.66973 1.66973 1.66973
      children [
        USE SPHERE_SHAPE
      ]
    }
  ]
  name "blue object 2"
  boundingObject USE SPHERE_SHAPE
}
DEF BLUE_OBJECT3 Solid {
  translation -2.8124 1.527 0.27
  rotation -0.5652341910457974 0.4124661394111039 0.714410241466416 -1.592006
  children [
    Transform {
      scale 1.64056 1.64056 1.64056
      children [
        USE SPHERE_SHAPE
      ]
    }
  ]
  name "blue object 3"
  boundingObject USE SPHERE_SHAPE
}
DEF PINK_OBJECT1 Solid {
  translation 1.8848 1.5955 0.55
  children [
    Transform {
      scale 1.46599 1.46599 1.46599
      children [
        DEF CYLINDER_SHAPE Shape {
          appearance PBRAppearance {
            baseColor 1 0.1 0.3
            roughness 0.16827074099999995
            metalness 0
          }
          geometry Cylinder {
            height 0.8
            radius 0.3
            subdivision 20
          }
        }
      ]
    }
  ]
  name "pink object 1"
  boundingObject USE CYLINDER_SHAPE
}
DEF PINK_OBJECT2 Solid {
  translation -0.3676 3.1247 0.47
  children [
    Transform {
      scale 1.34833 1.34833 1.34833
      children [
        USE CYLINDER_SHAPE
      ]
    }
  ]
  name "pink object 2"
  boundingObject USE CYLINDER_SHAPE
}
DEF PINK_OBJECT3 Solid {
  translation -0.5829 -2.5176 0.54
  children [
    Transform {
      scale 1.51649 1.51649 1.51649
      children [
        USE CYLINDER_SHAPE
      ]
    }
  ]
  name "pink object 3"
  boundingObject USE CYLINDER_SHAPE
}
DEF ROBOT Robot {
  translation -1.4648921116000043e-10 8.353957778924245e-11 -0.00015995753391026546
  rotation -0.017209767307864925 0.9998518763534888 0.0002219495818087776 3.972704112663028e-05
  children [
    Pose {
      translation 0 0 0.1245
      rotation 0 0 1 -1.570796
      children [
        Shape {
          appearance PBRAppearance {
            baseColor 0.74902 0.74902 0.74902
            roughness 1
            metalness 0
          }
          geometry DEF BODY Cylinder {
            height 0.24
            radius 0.135
          }
        }
      ]
    }
    HingeJoint {
      jointParameters HingeJointParameters {
        position -3.969765031676963e-07
        axis 0 1 0
        anchor 0 0 0.075
      }
      device [
        RotationalMotor {
          name "left wheel motor"
          consumptionFactor 70
          maxVelocity 100
        }
        PositionSensor {
          name "left wheel sensor"
        }
      ]
      endPoint Solid {
        translation 0 0.13500000000000004 0.075
        rotation 0.13448714572628906 -0.13448714572634077 -0.9817466145950174 1.5892170533881989
        children [
          DEF WHEEL Pose {
            rotation 0.577656895078166 0.5771968951617173 -0.5771968951617173 -2.093935
            children [
              Shape {
                appearance PBRAppearance {
                  baseColor 0.301961 0.301961 0.301961
                  roughness 1
                  metalness 0
                }
                geometry Cylinder {
                  height 0.03
                  radius 0.075
                }
              }
            ]
          }
        ]
        name "left wheel"
        boundingObject USE WHEEL
        physics DEF PHYSICS_WHEEL Physics {
          density -1
          mass 0.05
        }
        linearVelocity 1.39144477268246e-05 -8.19103198154829e-11 2.3571949771577707e-10
        angularVelocity 1.7779078972154477e-09 0.00018548351868251183 2.1171442118419385e-06
      }
    }
    HingeJoint {
      jointParameters HingeJointParameters {
        position 3.969750905392336e-07
        axis 0 1 0
        anchor 0 0 0.075
      }
      device [
        RotationalMotor {
          name "right wheel motor"
          consumptionFactor 70
          maxVelocity 100
        }
        PositionSensor {
          name "right wheel sensor"
        }
      ]
      endPoint Solid {
        translation 0 -0.13500000000000004 0.075
        rotation -0.062357197889716894 0.06235719788969928 -0.9961039904260437 1.574700024754215
        children [
          USE WHEEL
        ]
        name "right wheel"
        boundingObject USE WHEEL
        physics USE PHYSICS_WHEEL
        linearVelocity 1.4502376049847377e-05 -1.842193044078773e-10 -2.3350800450712496e-10
        angularVelocity 1.7702922332609597e-09 0.00019342096090895028 2.1170525688667996e-06
      }
    }
    DEF US0 DistanceSensor {
      translation 0.115 0.07 0.189
      rotation 0 0 -1 -0.499205
      children [
        DEF SONAR_SENSOR Pose {
          rotation 0.577656895078166 0.5771968951617173 -0.5771968951617173 -2.093935
          children [
            Shape {
              appearance PBRAppearance {
                baseColor 0.301961 0.301961 0.301961
                roughness 1
                metalness 0
              }
              geometry Cylinder {
                height 0.01
                radius 0.024
              }
            }
          ]
        }
      ]
      name "us0"
      lookupTable [
        0 0.7 0.01
        2 0 0
      ]
      type "sonar"
      numberOfRays 20
    }
    DEF US1 DistanceSensor {
      translation 0.115 -0.07 0.189
      rotation 0 0 1 -0.500795
      children [
        USE SONAR_SENSOR
      ]
      name "us1"
      lookupTable [
        0 0.7 0.1
        2 0 0
      ]
      type "sonar"
      numberOfRays 20
    }
    DEF LIDAR Lidar {
      translation 0 0 0.45
      children [
        Transform {
          translation 0 0 -0.01
          rotation 0 0 -1 1.570796
          scale 6 5 3
          children [
            DEF STRUCTURE_AXES Shape {
              appearance Appearance {
                material Material {
                  diffuseColor 0.02 0.02 0.02
                }
              }
              geometry IndexedLineSet {
                coord Coordinate {
                  point [
                    0 0 0.01
                    0.01 0 -0.08
                    -0.01 0 -0.08
                    0 0.01 -0.08
                    0 -0.01 -0.08
                  ]
                }
                coordIndex [
                  0, 1, 0, 2, 0, 3, 0, 4
                ]
              }
            }
          ]
        }
      ]
      tiltAngle -0.1
      horizontalResolution 256
      fieldOfView 1.57
      numberOfLayers 6
      near 0.05
      minRange 0.05
      maxRange 8
      type "rotating"
      noise 0.1
      defaultFrequency 2
      rotatingHead Solid {
        children [
          Pose {
            translation 0.03 0 0
            rotation 0 0 1 3.14159
            children [
              DEF LENS Shape {
                appearance PBRAppearance {
                  baseColor 0 0 0
                  roughness 1.1102230246251565e-16
                  metalness 0
                }
                geometry Sphere {
                  radius 0.015
                  subdivision 2
                }
              }
            ]
          }
          DEF CAMERA_SHAPE Pose {
            rotation -0.5771978956908259 0.5776548956082386 0.5771978956908259 -2.093935
            children [
              DEF CAMERA_OUTLINE Shape {
                appearance PBRAppearance {
                  baseColor 0.898039 0.898039 0.898039
                  roughness 1
                  metalness 0
                }
                geometry Cylinder {
                  height 0.06
                  radius 0.024
                }
              }
            ]
          }
        ]
      }
    }
  ]
  name "MyBot"
  boundingObject Pose {
    translation 0 0 0.1245
    rotation 0 0 1 -1.570796
    children [
      USE BODY
    ]
  }
  physics Physics {
    density -1
    mass 1.5
    centerOfMass [
      0 0 0.15
    ]
  }
  controller "my_lidar_controller"
  linearVelocity 2.8417168424341208e-05 -2.600749169300797e-10 -5.499710201591648e-10
  angularVelocity 1.7740539432562545e-09 0.00018945231027126078 2.117058016371943e-06
}
